Workbook
Name EVALUATION: #REF!
Name ITEMS_DE_SECURITÉ: #REF!
Name SALLE: [1]LD!$A$3:$A$50

Sheet Évaluation
D2: Poids | E2: COST MATERIEL | F2: Marge % | G2: Vendant | H2: Profit | I2: QTÉ HR INSTAL | J2: QTÉ HR PM | K2: COST MHRS | L2: Marge % | M2: Vendant | N2: Profit | O2: COST Sub | P2: Marge % | Q2: Vendant | R2: Profit | T2: Hébergement | U2: Déplacement | V2: Marge % | W2: Vendant | X2: Sous-Total | Y2: Risque | Z2: Total
C3: Feuil1 | D3: =Z3/$Z$10 -> 1 | G3: =E3/((100-F3)*0.01) -> 0 | H3: =G3-E3 -> 0 | I3: =SUM(B218:B225) -> 264 | J3: =SUM(B226:B227) -> 40 | K3: =(I3+J3)*D217 -> 22800 | L3: =100*(G218-D218)/G218 -> 40 | M3: =K3/((100-L3)*0.01) -> 38000 | N3: =M3-K3 -> 15200 | P3: 0.2 | Q3: =O3/(1-P3) -> 0 | R3: =Q3-O3 -> 0 | V3: 0.2 | W3: =SUM(S3:U3)/(1-V3) -> 0 | X3: =M3+G3+Q3+W3 -> 38000 | Z3: =X3+SUM(Y3:Y3) -> 38000
D4: =Z4/$Z$10 -> 0 | G4: =E4/(1-F4) -> 0 | H4: =G4-E4 -> 0 | M4: =K4/(1-L4) -> 0 | N4: =M4-K4 -> 0 | P4: 0.15 | Q4: =O4/(1-P4) -> 0 | R4: =Q4-O4 -> 0 | V4: 0.2 | W4: =SUM(S4:U4)/(1-V4) -> 0 | X4: =M4+G4+Q4+W4 -> 0 | Z4: =X4+SUM(Y4:Y4) -> 0
C5: PERDIEM | D5: =Z5/$Z$10 -> 0 | E5: =H12/8*70*7/5+N("7 jours versus 5 jours - weekend") -> 0 | G5: =E5/(1-F5) -> 0 | H5: =G5-E5 -> 0 | M5: =K5/(1-L5) -> 0 | N5: =M5-K5 -> 0 | P5: 0.2 | Q5: =O5/(1-P5) -> 0 | R5: =Q5-O5 -> 0 | V5: 0.2 | W5: =SUM(S5:U5)/(1-V5) -> 0 | X5: =M5+G5+Q5+W5 -> 0 | Z5: =X5+SUM(Y5:Y5) -> 0
D6: =Z6/$Z$10 -> 0 | G6: =E6/(1-F6) -> 0 | H6: =G6-E6 -> 0 | M6: =K6/(1-L6) -> 0 | N6: =M6-K6 -> 0 | P6: 0.2 | Q6: =O6/(1-P6) -> 0 | R6: =Q6-O6 -> 0 | V6: 0.2 | W6: =SUM(S6:U6)/(1-V6) -> 0 | X6: =M6+G6+Q6+W6 -> 0 | Z6: =X6+SUM(Y6:Y6) -> 0
C7: CAUTIONNEMENT | D7: =Z7/$Z$10 -> 0 | F7: 0.1 | G7: =E7/(1-F7) -> 0 | H7: =G7-E7 -> 0 | M7: =K7/(1-L7) -> 0 | N7: =M7-K7 -> 0 | Q7: =O7/(1-P7) -> 0 | R7: =Q7-O7 -> 0 | V7: 0.2 | W7: =SUM(S7:U7)/(1-V7) -> 0 | X7: =M7+G7+Q7+W7 -> 0 | Z7: =X7+SUM(Y7:Y7) -> 0
C8: DOC + MEETINGS | D8: =Z8/$Z$10 -> 0 | G8: =E8/(1-F8) -> 0 | H8: =G8-E8 -> 0 | M8: =K8/(1-L8) -> 0 | N8: =M8-K8 -> 0 | Q8: =O8/(1-P8) -> 0 | R8: =Q8-O8 -> 0 | V8: 0.2 | W8: =SUM(S8:U8)/(1-V8) -> 0 | X8: =M8+G8+Q8+W8 -> 0 | Z8: =X8+SUM(Y8:Y8) -> 0
C9: RISQUE | D9: =Z9/$Z$10 -> 0 | G9: =E9/(1-F9) -> 0 | H9: =G9-E9 -> 0 | M9: =K9/(1-L9) -> 0 | N9: =M9-K9 -> 0 | Q9: =O9/(1-P9) -> 0 | R9: =Q9-O9 -> 0 | V9: 0.2 | W9: =SUM(S9:U9)/(1-V9) -> 0 | X9: =M9+G9+Q9+W9 -> 0 | Z9: =X9+SUM(Y9:Y9) -> 0
C10: TOTAL | E10: =SUM(E3:E9) -> 0 | G10: =SUM(G3:G9) -> 0 | H10: =SUM(H3:H9) -> 0 | I10: =SUM(I3:I9) -> 264 | K10: =SUM(K3:K9) -> 22800 | M10: =SUM(M3:M9) -> 38000 | N10: =SUM(N3:N9) -> 15200 | O10: =SUM(O3:O9) -> 0 | Q10: =SUM(Q3:Q9) -> 0 | R10: =SUM(R3:R9) -> 0 | S10: =SUM(S3:S9) -> 0 | T10: =SUM(T3:T9) -> 0 | U10: =SUM(U3:U9) -> 0 | W10: =SUM(W3:W9) -> 0 | X10: =SUM(X3:X9) -> 38000 | Y10: =SUM(Y3:Y9) -> 0 | Z10: =SUM(Z3:Z9) -> 38000
C12: TRAVAILLER PAR MARK-UP | I12: ÉQUIPEMENT | K12: TOTAL COST | M12: TOTAL VENDANT | O12: % MARGE | S12: Tableau de risque
D13: COUTANT | E13: % | F13: VENDANT | G13: PROFIT | I13: MATÉRIEL | K13: =J146 -> 34644.57 | M13: =M146 -> 46192.76 | O13: =IF(M13=0,0,(M13-K13)/M13) -> 0.25 | S13: Description | V13: Montant ($) | W13: Chance (%) | X13: Total ($)
B14: 0 | C14: MATÉRIEL | D14: =J146+H169+H186+E203 -> 36230.353 | E14: 20 | F14: =D14/((100-E14)*0.01) -> 45287.941 | G14: =F14-D14 -> 9057.5882 | I14: CÂBLE | K14: =H169 -> 0 | M14: =K169 -> 0 | O14: =IF(M14=0,0,(M14-K14)/M14) -> 0 | R14: AUTRES VIDÉO | X14: =V14*W14 -> 0
C15: SOUS-TRAITANT | D15: =E213 -> 0 | E15: 20 | F15: =D15/((100-E15)*0.01) -> 0 | G15: =F15-D15 -> 0 | I15: QUINCAILLERIE | K15: =H186 -> 0 | M15: =K186 -> 0 | O15: =IF(M15=0,0,(M15-K15)/M15) -> 0 | X15: =V15*W15 -> 0
C16: MAIN D'ŒUVRE | D16: =E232 -> 23600 | E16: 20 | F16: =D16/((100-E16)*0.01) -> 29500 | G16: =F16-D16 -> 5900 | I16: SOUS-TRAITANT | K16: =E213 -> 0 | M16: =H213 -> 0 | O16: =IF(M16=0,0,(M16-K16)/M16) -> 0 | X16: =V16*W16 -> 0
B17: 0 | C17: GESTION | D17: =E226+E227 -> 3800 | E17: 20 | F17: =D17/((100-E17)*0.01) -> 4750 | G17: =F17-D17 -> 950 | X17: =V17*W17 -> 0
D18: =SUM(D14:D17) -> 63630.353 | E18: =100-((D18/F18)*100) -> 20 | F18: =SUM(F14:F17) -> 79537.941 | G18: =SUM(G14:G17) -> 15907.588 | I18: TOTAL MATÉRIEL | K18: =SUM(K13:L16) -> 34644.57 | M18: =SUM(M13:N16) -> 46192.76 | O18: =IF(M18=0,0,(M18-K18)/M18) -> 0.25 | X18: =V18*W18 -> 0
I19: MAIN D'ŒUVRE | K19: TOTAL COST | M19: TOTAL VENDANT | O19: % MARGE | X19: =V19*W19 -> 0
C20: TRAVAILLER PAR PROFIT SOUHAITÉ | X20: =V20*W20 -> 0
D21: COUTANT | E21: % | F21: VENDANT | G21: PROFIT | I21: FRAIS GÉNÉRAUX | K21: =E203 -> 1585.7828 | M21: =H203 -> 1671.4971 | O21: =IF(M21=0,0,(M21-K21)/M21) -> 0.051279949 | X21: =V21*W21 -> 0
D22: =D18 -> 63630.353 | E22: =100-((D22/F22)*100) -> 0 | F22: =G22+D22 -> 63630.353 | G22: 0 | I22: INSTALLATION | K22: =E232 -> 23600 | M22: =H232 -> 39333.333 | O22: =IF(M22=0,0,(M22-K22)/M22) -> 0.4 | X22: =V22*W22 -> 0
X23: =V23*W23 -> 0
C24: SELON PRIX VENDANT | I24: TOTAL MAIN D'ŒUVRE | K24: =SUM(K21:L22) -> 25185.783 | M24: =SUM(M21:N22) -> 41004.83 | O24: =IF(M24=0,0,(M24-K24)/M24) -> 0.38578498 | X24: =V24*W24 -> 0
D25: COUTANT | E25: % | F25: VENDANT | G25: PROFIT | X25: =V25*W25 -> 0
D26: =D18 -> 63630.353 | E26: =100-((D26/F26)*100) -> #DIV/0! | F26: 0 | G26: =F26-D26 -> -63630.353 | I26: GRAND TOTAL | K26: =SUM(K18,K24) -> 59830.353 | M26: =SUM(M18,M24) -> 87197.59 | O26: =IF(M26=0,0,(M26-K26)/M26) -> 0.31385314 | X26: =V26*W26 -> 0
X27: =V27*W27 -> 0
C28: TRAVAILLER PAR MARK-UP TOTAL | X28: =V28*W28 -> 0
D29: COUTANT | E29: % | F29: VENDANT | G29: PROFIT | X29: =V29*W29 -> 0
D30: =D18 -> 63630.353 | E30: 25 | F30: =D30/((100-E30)*0.01) -> 84840.47 | G30: =F30-D30 -> 21210.118 | X30: =V30*W30 -> 0
X31: =V31*W31 -> 0
X32: =SUM(X14:X31) -> 0
B34: {=_FV(A36,"Price")} -> 1.3693 | C34: USD → CAN | D34: Client : | E34: LC Connect
B35: {=1/_FV(A36,"Price")} -> 0.73030015 | C35: CAN → USD | D35: Projet : | E35: École secondaire Prévost
A36: #VALUE! | B36: Matériel
B37: QTÉ | C37: # PRODUIT / PIÈCE | D37: Manufacturier | E37: Fournisseur | F37: EQUIPMENTS / DESCRIPTION | G37: MSRP | H37: ESCOMPTE | I37: UNIT COST | J37: TOTAL COST | K37: % MARGE | L37: VENDANT UNIT | M37: TOTAL VENDANT | N37: INST. UNITAIRE | O37: INST. TOTAL | P37: PROG. UNITAIRE | Q37: PROG. TOTAL | R37: COMMANDÉ | S37: RECU | T37: COMMENTAIRES
K38: 25
A39: FALSE | J39: =I39*B39 -> 0 | K39: =$K$38 -> 25 | L39: =I39/((100-K39)*0.01) -> 0 | M39: =B39*L39 -> 0 | O39: =N39*B39 -> 0 | Q39: =P39*B39 -> 0 | W39: Boitier d'alimentation | X39: Lecteur de carte | Y39: Interrupteur à clé | Z39: Bouton ouverture de porte (2 chaque) | AB39: # Porte | AC39: Décompte | AE39: Équipement | AF39: Qté
A40: FALSE | F40: Boîtier d'alimentation (1 par porte) | J40: =I40*B40 -> 0 | K40: =$K$38 -> 25 | L40: =I40/((100-K40)*0.01) -> 0 | M40: =B40*L40 -> 0 | O40: =N40*B40 -> 0 | Q40: =P40*B40 -> 0 | W40: 5 | X40: 5 ext | Y40: 5 | Z40: 5 | AB40: 5 | AC40: 1 | AE40: Boitier d'alimentation | AF40: {=SUMPRODUCT((W40:W66<>"")*IFERROR(VLOOKUP(W40:W66,$AB$40:$AC$68,2,FALSE),0))} -> 43
A41: TRUE | B41: 43 | C41: AQD1 | D41: Securitron | E41: ADI | F41: Proprietary Power Supply, Dual Voltage, UL Listed | I41: 223.29 | J41: =I41*B41 -> 9601.47 | K41: =$K$38 -> 25 | L41: =I41/((100-K41)*0.01) -> 297.72 | M41: =B41*L41 -> 12801.96 | N41: 1 | O41: =N41*B41 -> 43 | Q41: =P41*B41 -> 0 | W41: 10 | X41: 17 ext | Y41: 10 | Z41: 34 | AB41: 10 | AC41: 3 | AE41: Lecteur intérieur | AF41: 4 | AG41: 2 au premier 2 au 2e
A42: FALSE | C42: AQD2
A43: FALSE | C43: AQD4
...

Sheet Demande de prix
B2: ADI | G2: WESCO
B3: QTÉ | C3: # PRODUIT / PIÈCE | D3: EQUIPMENTS / DESCRIPTION | E3: PRIX COUT. | G3: QTÉ | H3: # PRODUIT / PIÈCE | I3: EQUIPMENTS / DESCRIPTION | J3: PRIX COUT. | L3: QTÉ | M3: # PRODUIT / PIÈCE | N3: EQUIPMENTS / DESCRIPTION | O3: PRIX COUT. | Q3: QTÉ | R3: # PRODUIT / PIÈCE | S3: EQUIPMENTS / DESCRIPTION | T3: PRIX COUT. | V3: QTÉ | W3: # PRODUIT / PIÈCE | X3: EQUIPMENTS / DESCRIPTION | Y3: PRIX COUT. | AA3: QTÉ | AB3: # PRODUIT / PIÈCE | AC3: EQUIPMENTS / DESCRIPTION | AD3: PRIX COUT. | AF3: QTÉ | AG3: # PRODUIT / PIÈCE | AH3: EQUIPMENTS / DESCRIPTION | AI3: PRIX COUT. | AK3: QTÉ | AL3: # PRODUIT / PIÈCE | AM3: EQUIPMENTS / DESCRIPTION | AN3: PRIX COUT. | AP3: QTÉ | AQ3: # PRODUIT / PIÈCE | AR3: EQUIPMENTS / DESCRIPTION | AS3: PRIX COUT.
A4: {=_xlfn.LET( _xlpm.données, _xlfn._xlws.FILTER(_xlfn.CHOOSECOLS(Évaluation!$B$38:$S$146, 1, 2, 5, 9), (Évaluation!$E$38:$E$146=B$2), ""), _xlfn.HSTACK(_xlfn.EXPAND("", ROWS(_xlpm.données), 1, ""), _xlpm.données) )} | B4: 43 | C4: AQD1 | D4: Proprietary Power Supply, Dual Voltage, UL Listed | E4: 9601.47 | F4: {=IF(G$2="", "", _xlfn.LET(_xlpm.d, _xlfn._xlws.FILTER(_xlfn.CHOOSECOLS(Évaluation!$B$38:$S$146, 1, 2, 5, 8), (Évaluation!$E$38:$E$146=G$2), ""), _xlfn.HSTACK(_xlfn.EXPAND("", ROWS(_xlpm.d), 1, ""), _xlpm.d)))} | G4: 43 | H4: B-24-5 | I4: Power Supply Battery, Lead Acid, 24 Volt DC, 5 Amp-Hr | J4: 136.11 | K4: {=IF(L$2="", "", _xlfn.LET(_xlpm.d, _xlfn._xlws.FILTER(_xlfn.CHOOSECOLS(Évaluation!$B$38:$S$146, 1, 2, 5, 8), (Évaluation!$E$38:$E$146=L$2), ""), _xlfn.HSTACK(_xlfn.EXPAND("", ROWS(_xlpm.d), 1, ""), _xlpm.d)))} | P4: {=IF(Q$2="", "", _xlfn.LET(_xlpm.d, _xlfn._xlws.FILTER(_xlfn.CHOOSECOLS(Évaluation!$B$38:$S$146, 1, 2, 5, 8), (Évaluation!$E$38:$E$146=Q$2), ""), _xlfn.HSTACK(_xlfn.EXPAND("", ROWS(_xlpm.d), 1, ""), _xlpm.d)))} | U4: {=IF(V$2="", "", _xlfn.LET(_xlpm.d, _xlfn._xlws.FILTER(_xlfn.CHOOSECOLS(Évaluation!$B$38:$S$146, 1, 2, 5, 8), (Évaluation!$E$38:$E$146=V$2), ""), _xlfn.HSTACK(_xlfn.EXPAND("", ROWS(_xlpm.d), 1, ""), _xlpm.d)))} | Z4: {=IF(AA$2="", "", _xlfn.LET(_xlpm.d, _xlfn._xlws.FILTER(_xlfn.CHOOSECOLS(Évaluation!$B$38:$S$146, 1, 2, 5, 8), (Évaluation!$E$38:$E$146=AA$2), ""), _xlfn.HSTACK(_xlfn.EXPAND("", ROWS(_xlpm.d), 1, ""), _xlpm.d)))} | AE4: {=IF(AF$2="", "", _xlfn.LET(_xlpm.d, _xlfn._xlws.FILTER(_xlfn.CHOOSECOLS(Évaluation!$B$38:$S$146, 1, 2, 5, 8), (Évaluation!$E$38:$E$146=AF$2), ""), _xlfn.HSTACK(_xlfn.EXPAND("", ROWS(_xlpm.d), 1, ""), _xlpm.d)))} | AJ4: {=IF(AK$2="", "", _xlfn.LET(_xlpm.d, _xlfn._xlws.FILTER(_xlfn.CHOOSECOLS(Évaluation!$B$38:$S$146, 1, 2, 5, 8), (Évaluation!$E$38:$E$146=AK$2), ""), _xlfn.HSTACK(_xlfn.EXPAND("", ROWS(_xlpm.d), 1, ""), _xlpm.d)))} | AO4: {=IF(AP$2="", "", _xlfn.LET(_xlpm.d, _xlfn._xlws.FILTER(_xlfn.CHOOSECOLS(Évaluation!$B$38:$S$146, 1, 2, 5, 8), (Évaluation!$E$38:$E$146=AP$2), ""), _xlfn.HSTACK(_xlfn.EXPAND("", ROWS(_xlpm.d), 1, ""), _xlpm.d)))}
B5: 43 | C5: PDB-8C1R2 | D5: Power Distribution Board, PTC with Relays | E5: 4379.55
B6: 16 | C6: 40NKS-00-000000 | D6: Lecteur de carte extérieur | E6: 5001.28
B7: 200 | C7: 5106RGGMNM | D7: Cartes d'accès | E7: 2102
B8: 1 | C8: FPO150-2C82D8E8A | D8: Contrôleurs de portes | E8: 0
B9: 2 | C9: NP7-12 | D9: Batteries 12v 7Ah | E9: 103.76
B10: 2 | C10: KT-APERAH30R12-C | D10: Aperio RS485 Network Hub, Supports up to 8 Locks | E10: 804.56

Sheet Ventilation
B2: Ventilation des prix
B3: QTÉ | C3: # PRODUIT / PIÈCE | D3: EQUIPMENTS / DESCRIPTION | E3: COÛT UNITAIRE | F3: SOUS-TOTAL
A4: {=_xlfn.LET( _xlpm.chk_mat, $I$5=TRUE, _xlpm.chk_cab, $I$6=TRUE, _xlpm.chk_qnc, $I$7=TRUE, _xlpm.chk_div, $I$8=TRUE, _xlpm.chk_mo, $I$9=TRUE, _xlpm.chk_mat_header, $I$12=TRUE, _xlpm.chk_mat_subtotal, AND($I$5=TRUE, $I$13=TRUE), _xlpm.chk_total, $I$14=TRUE, _xlpm.f, _xlfn._xlws.FILTER(_xlfn.CHOOSECOLS(Évaluation!$A$38:$S$146, 2, 3, 6, 12), Évaluation!$A$38:$A$146=TRUE, "VIDE"), _xlpm.mat_ok, AND(_xlpm.chk_mat, INDEX(_xlpm.f,1,1)<>"VIDE"), _xlpm.has_mat, INDEX(_xlpm.f,1,1)<>"VIDE", _xlpm.qty, INDEX(_xlpm.f,,1), _xlpm.id, INDEX(_xlpm.f,,2), _xlpm.desc, INDEX(_xlpm.f,,3), _xlpm.u_sell, INDEX(_xlpm.f,,4), _xlpm.total, _xlpm.qty * _xlpm.u_sell, _xlpm.mat_ventile_sum, IF(_xlpm.has_mat, SUM(_xlpm.total), 0), _xlpm.mat_header_amount, IF(AND(NOT(_xlpm.chk_mat_subtotal), _xlpm.mat_ventile_sum<>0), _xlpm.mat_ventile_sum, ""), _xlpm.mat_header, _xlfn.HSTACK("", "", "Matériel", "Équipements sélectionnés pour le projet", "", _xlpm.mat_header_amount), _xlpm.mat_detail, IF(_xlpm.mat_ok, _xlfn.HSTACK( _xlfn.EXPAND("", ROWS(_xlpm.f), 1, ""), IF(_xlpm.qty=0, "", _xlpm.qty), IF(_xlpm.id=0, "", _xlpm.id), IF(_xlpm.desc=0, "", _xlpm.desc), IF(_xlpm.u_sell=0, "", _xlpm.u_sell), IF(_xlpm.total=0, "", _xlpm.total) ), "" ), _xlpm.mat_subtotal_ligne, _xlfn.HSTACK("", "", "", "Sous-total matériel", "", IF(_xlpm.mat_ventile_sum=0, "", _xlpm.mat_ventile_sum)), _xlpm.cab_ligne, IF(AND(_xlpm.chk_cab, Évaluation!K169<>0), _xlfn.HSTACK("", "", "Câble", "Filerie et câblage pour le projet", "", Évaluation!K169), "" ), _xlpm.qnc_ligne, IF(AND(_xlpm.chk_qnc, Évaluation!K186<>0), _xlfn.HSTACK("", "", "Quincaillerie", "Supports, conduits, boîtes et accessoires", "", Évaluation!K186), "" ), _xlpm.div_ligne, IF(AND(_xlpm.chk_div, Évaluation!H203<>0), _xlfn.HSTACK("", "", "Frais divers", "Frais reliés à l'exécution du projet", "", Évaluation!H203), "" ), _xlpm.mo_ligne, IF(AND(_xlpm.chk_mo, Évaluation!H232<>0), _xlfn.HSTACK("", "", "Main d'œuvre", "Installation, programmation, mise en marche, gestion de projet", "", Évaluation!H232), "" ), _xlpm.vide, _xlfn.HSTACK("", "", "", "", "", ""), _xlpm.spacer, _xlfn.HSTACK("", "", " ", "", "", ""), _xlpm.mat_sum, IF(_xlpm.mat_ok, SUM(_xlpm.total), 0), _xlpm.cab_sum, IF(_xlpm.chk_cab, Évaluation!K169, 0), _xlpm.qnc_sum, IF(_xlpm.chk_qnc, Évaluation!K186, 0), _xlpm.div_sum, IF(_xlpm.chk_div, Évaluation!H203, 0), _xlpm.mo_sum, IF(_xlpm.chk_mo, Évaluation!H232, 0), _xlpm.grand_total, _xlpm.mat_sum + _xlpm.cab_sum + _xlpm.qnc_sum + _xlpm.div_sum + _xlpm.mo_sum, _xlpm.total_ligne, _xlfn.HSTACK("", "", "", "TOTAL", "", _xlpm.grand_total), _xlpm.sections, IFERROR( _xlfn.VSTACK( IF(AND(_xlpm.chk_mat_header, _xlpm.has_mat), _xlpm.mat_header, ""), IF(_xlpm.mat_ok, _xlpm.mat_detail, ""), IF(AND(_xlpm.chk_mat_subtotal, _xlpm.has_mat), _xlpm.mat_subtotal_ligne, ""), IF(AND(_xlpm.chk_mat, _xlpm.mat_ok), _xlpm.spacer, ""), IF(_xlpm.chk_cab, _xlpm.cab_ligne, ""), IF(_xlpm.chk_qnc, _xlpm.qnc_ligne, ""), IF(_xlpm.chk_div, _xlpm.div_ligne, ""), IF(_xlpm.chk_mo, _xlpm.mo_ligne, "") ), "" ), _xlpm.has_content, (INDEX(_xlpm.sections,,2)<>"")+(INDEX(_xlpm.sections,,3)<>"")+(INDEX(_xlpm.sections,,4)<>"")+(INDEX(_xlpm.sections,,6)<>""), _xlpm.clean, IFERROR(_xlfn._xlws.FILTER(_xlpm.sections, _xlpm.has_content>0), ""), _xlpm.show_total, AND(_xlpm.chk_total, _xlpm.grand_total<>0), _xlpm.result, IF(NOT(_xlpm.show_total), _xlpm.clean, _xlfn.VSTACK(_xlpm.clean, _xlpm.vide, _xlpm.total_ligne)), IFERROR(_xlpm.result, "") )} | C4: Matériel | D4: Équipements sélectionnés pour le projet | H4: Sections à afficher
B5: 43 | C5: AQD1 | D5: Proprietary Power Supply, Dual Voltage, UL Listed | E5: 297.72 | F5: 12801.96 | H5: Matériel | I5: TRUE
B6: 43 | C6: PDB-8C1R2 | D6: Power Distribution Board, PTC with Relays | E6: 135.8 | F6: 5839.4 | H6: Câble | I6: TRUE
B7: 43 | C7: B-24-5 | D7: Power Supply Battery, Lead Acid, 24 Volt DC, 5 Amp-Hr | E7: 181.48 | F7: 7803.64 | H7: Quincaillerie | I7: TRUE
B8: 4 | C8: xxx | D8: Lecteur de carte intérieur (raccorder et programmer seulement) | H8: Frais divers | I8: TRUE
B9: 16 | C9: 40NKS-00-000000 | D9: Lecteur de carte extérieur | E9: 416.77333 | F9: 6668.3733 | H9: Main d'œuvre | I9: TRUE
B10: 200 | C10: 5106RGGMNM | D10: Cartes d'accès | E10: 14.013333 | F10: 2802.6667
B11: 2 | C11: NP7-12 | D11: Batteries 12v 7Ah | E11: 69.173333 | F11: 138.34667 | H11: Autres options
B12: 2 | C12: M2150-8DBC-OSDP | D12: Symmetry M2150 8DBC OSDP 8 Reader Panel BOARD ONLY -20K | E12: 3513.8533 | F12: 7027.7067 | H12: En-tête matériel | I12: TRUE
B13: 1 | C13: MN-EN-LDBU-ENC1 | D13: Symmetry EN-LDBU MultiNODE Controller - ENC1 - 18Vac | E13: 2037.92 | F13: 2037.92 | H13: Sous-total matériel | I13: TRUE
B14: 2 | C14: KT-APERAH30R12-C | D14: Aperio RS485 Network Hub, Supports up to 8 Locks | E14: 536.37333 | F14: 1072.7467 | H14: Afficher total | I14: TRUE
B15: 24 | C15: xxx | D15: Bouton ouverture de porte
D16: Sous-total matériel | F16: 46192.76
C18: Frais divers | D18: Frais reliés à l'exécution du projet | F18: 1671.4971
C19: Main d'œuvre | D19: Installation, programmation, mise en marche, gestion de projet | F19: 39333.333
D21: TOTAL | F21: 87197.59

Sheet Opération
D1: Palantír
D3: Nom du projet :
D4: # du projet : | H4: # Soumission :
B6: PO#/Confirmation : | E6: Chargé projet : | H6: Rep :
B7: Date du booking : | E7: Start Date Est : | H7: Est. Comp :
B8: Bureau : | C8: Québec | E8: Project Type : | H8: Supply only : | I8: FALSE | M8: Sécurité | O8: ES | P8: SPM
B9: Mobilisation : | E9: Nouveau client : | F9: FALSE | H9: Réccurence : | I9: FALSE | M9: Télécom | O9: LDB | P9: Mike
M10: Développement | O10: AM | P10: Baba
B11: Client (facture) : | G11: Worksite (si idem à facture) : | J11: FALSE | M11: Barrière/Tourniquet | O11: JO | P11: Jatin
B12: Adresse : | D12: Province : | G12: Adresse : | I12: Province : | M12: Électrique | O12: JH | P12: Math
B13: Ville : | D13: Code postal : | G13: Ville : | I13: Code postal : | O13: LL | P13: Oli
B14: Contact : | D14: Email : | G14: Contact : | I14: Email : | O14: LFC | P14: Max
B15: Téléphone : | G15: Téléphone : | O15: DD
O16: AD
B17: End User (si idem à facture) : | E17: FALSE | G17: GC/EC (si idem à facture) : | J17: FALSE | O17: AB
B18: Adresse : | D18: Province : | G18: Adresse : | I18: Province : | O18: MB
B19: Ville : | D19: Code postal : | G19: Ville : | I19: Code postal :
B20: Contact : | D20: Email : | G20: Contact : | I20: Email :
B21: Téléphone : | G21: Téléphone :
B23: Code: | C23: Description: | D23: Heures/Unité: | E23: Cost ($): | F23: Total ($): | G23: Note(s):
B24: M | C24: Matériel | D24: 1 | E24: =Évaluation!J146 -> 34644.57 | F24: =D24*E24 -> 34644.57
B25: C | C25: Cable | D25: 1 | E25: =Évaluation!H169 -> 0 | F25: =D25*E25 -> 0
B26: Q | C26: Quincaillerie | D26: 1 | E26: =Évaluation!H186 -> 0 | F26: =D26*E26 -> 0
B27: G | C27: Frais Généraux | D27: 1 | E27: =Évaluation!E203 -> 1585.7828 | F27: =D27*E27 -> 1585.7828
B28: S | C28: Sous-Traitant | F28: =D28*E28 -> 0
C29: Libre | F29: =D29*E29 -> 0
C30: Libre | F30: =D30*E30 -> 0
B31: LP | C31: Labour - PM | D31: =Évaluation!B226 -> 40 | E31: 95 | F31: =D31*E31 -> 3800 | G31: Travaux a l'heure @ 150$h
B32: LA | C32: Labour - Architecte | E32: 95 | F32: =D32*E32 -> 0 | G32: Travaux a l'heure @ 150$h
B33: LD | C33: Labour - Design/Draft | D33: =Évaluation!B227 -> 0 | E33: 95 | F33: =D33*E33 -> 0
B34: LT | C34: Labour - Installer | D34: =SUM(Évaluation!B218:B221,Évaluation!B225) -> 229 | E34: 75 | F34: =D34*E34 -> 17175 | G34: Travaux a l'heure @ 143,75$h
B35: LG | C35: Labour - Prog/Mise. | D35: =SUM(Évaluation!B222:B224) -> 35 | E35: 75 | F35: =D35*E35 -> 2625
B36: LV | C36: Labour - DEV | D36: =Évaluation!B228 -> 0 | E36: 95 | F36: =D36*E36 -> 0
B37: LO | C37: Labour - Autre | D37: =SUM(Évaluation!B231,Évaluation!B235) -> 0 | E37: 75 | F37: =D37*E37 -> 0
B38: Total | C38: Labour | F38: =SUM(F31:F37) -> 23600
B40: Note(s)interne: | G40: Coutant Total ($) | H40: =SUM(F24:F37) -> 59830.353
G41: GM ($) | H41: =H43*H42 -> 27367.238
G42: GM (%) | H42: =(H43-H40)/H43 -> 0.31385314
G43: Vendant Total ($) | H43: =Évaluation!M26 -> 87197.59
G44: TPS | H44: =H43*5% -> 4359.8795
...

Sheet TakeOff Accès
A1: No. Portes | B1: Nombres de Detail ou Points sur le plan | C1: Groupe de portes | D1: Distance (M) | E1: Descriptions au plan | F1: Local Panneau CP | H1: Nombre de Battant | I1: Séquence type no. | J1: =[1]Groupe!J7 -> Lecteur Entrée - | K1: =[1]Groupe!K7 -> Lecteur Sortie - | L1: =[1]Groupe!L7 -> Lecteur avec clavier | M1: Lecteur USB | N1: Licence intégration Bosch intrusion | O1: Licence client Genetec | P1: =[1]Groupe!P7 -> Contact Magnétique - | Q1: =[1]Groupe!Q7 -> Contact de porte de Garage | R1: =[1]Groupe!R7 -> Requête de Sortie - | S1: =[1]Groupe!S7 -> Det. Requête de Sortie - | T1: =[1]Groupe!T7 -> Etat Barre Panique élect. | U1: =[1]Groupe!U7 -> Station Manuelle Bleu | V1: =[1]Groupe!V7 -> Requete sortie intégré | W1: =[1]Groupe!W7 -> Interrupteur à Clé | ... Z1: =[1]Groupe!Z7 -> Gache Monitrice | AA1: Barre panique mécanique avec RX | AB1: =[1]Groupe!AB7 -> Clé Contournement | AC1: =[1]Groupe!AC7 -> Gâche Électrique - | AD1: =[1]Groupe!AD7 -> Électro-Aimant - | AE1: Serrure électrifiée avec requête | AF1: =[1]Groupe!AF7 -> Alarme Sonore(Hrn) - | AG1: Barre panique électrifiée avec Rex | AH1: =[1]Groupe!AH7 -> Electro-aimanr 3/15 | AI1: Barre panique 3/15 | AJ1: =[1]Groupe!AJ7 -> (Relai Lock/Unlock) | AK1: =[1]Groupe!AK7 -> Operateur Porte- | AL1: =[1]Groupe!AL7 -> Bouton ouverture | AM1: =[1]Groupe!AM7 -> Relais Alarme Incendie | AN1: =[1]Groupe!AN7 -> Borniers | AO1: =[1]Groupe!AO7 -> retenue Magnétique | AP1: =[1]Groupe!AP7 -> Boitier d'alimentation | AQ1: =[1]Groupe!AQ7 -> Transfert de courant | AR1: =[1]Groupe!AR7 -> Surveillance Panneau- | AS1: ITEMS | AT1: PTS Lecteurs | AU1: PTS INPUT | AV1: PTS OUTPUT | AX1: Câble 22/4 | AY1: Câble 18/2 | AZ1: Câble OSDP 24/2 | BA1: Câble 18/4 | BB1: Câble 18/8 | BC1: Câble 16/2 | BD1: Câble 22/6 | BE1: Câble com 22/4 blindé
H2: # | I2: SEQ | J2: =[1]Groupe!J8 -> LE | K2: =[1]Groupe!K8 -> LS | L2: =[1]Groupe!L8 -> LCI | M2: =[1]Groupe!M8 -> CN | N2: =[1]Groupe!N8 -> INT | O2: =[1]Groupe!O8 -> MA | P2: =[1]Groupe!P8 -> CM | Q2: =[1]Groupe!Q8 -> CMG | ... AR2: =[1]Groupe!AR8 -> TMP
J3: =J947 -> 0 | K3: =K947 -> 0 | L3: =L947 -> 0 | M3: =M947 -> 0 | N3: =N947 -> 0 | O3: =O947 -> 0 | P3: =P947 -> 0 | Q3: =Q947 -> 0 | ... AR3: =AR947 -> 0
H4: 0
AS5: =SUM(J5:AR5) -> 0 | AT5: =SUM(J5:O5) -> 0 | AU5: =SUM(P5:Z5) -> 0 | AV5: =SUM(AA5:AJ5) -> 0
AS6: =SUM(J6:AR6) -> 0 | AT6: =SUM(J6:O6) -> 0 | AU6: =SUM(P6:Z6) -> 0 | AV6: =SUM(AA6:AJ6) -> 0 | AX6: =D6*(P6+Q6+AL6+AE6+AA6+Z6+Y6+X6+AG6) -> 0 | AY6: =D6*(J6+K6+L6+AD6+AE6) -> 0 | AZ6: =D6*(J6+K6+L6) -> 0 | BA6: =D6*AC6 -> 0 | BB6: =D6*(AH6+AI6) -> 0 | BC6: =D6*(AH6+AI6) -> 0 | BD6: =D6*(AK6+W6) -> 0
AS7: =SUM(J7:AR7) -> 0 | AT7: =SUM(J7:O7) -> 0 | AU7: =SUM(P7:Z7) -> 0 | AV7: =SUM(AA7:AJ7) -> 0 | AX7: =D7*(P7+Q7+AL7+AE7+AA7+Z7+Y7+X7+AG7) -> 0 | AY7: =D7*(J7+K7+L7+AD7+AE7) -> 0 | AZ7: =D7*(J7+K7+L7) -> 0 | BA7: =D7*AC7 -> 0 | BB7: =D7*(AH7+AI7) -> 0 | BC7: =D7*(AH7+AI7) -> 0 | BD7: =D7*(AK7+W7) -> 0
AS8: =SUM(J8:AR8) -> 0 | AT8: =SUM(J8:O8) -> 0 | AU8: =SUM(P8:Z8) -> 0 | AV8: =SUM(AA8:AJ8) -> 0 | AX8: =D8*(P8+Q8+AL8+AE8+AA8+Z8+Y8+X8+AG8) -> 0 | AY8: =D8*(J8+K8+L8+AD8+AE8) -> 0 | AZ8: =D8*(J8+K8+L8) -> 0 | BA8: =D8*AC8 -> 0 | BB8: =D8*(AH8+AI8) -> 0 | BC8: =D8*(AH8+AI8) -> 0 | BD8: =D8*(AK8+W8) -> 0
AS9: =SUM(J9:AR9) -> 0 | AT9: =SUM(J9:O9) -> 0 | AU9: =SUM(P9:Z9) -> 0 | AV9: =SUM(AA9:AJ9) -> 0 | AX9: =D9*(P9+Q9+AL9+AE9+AA9+Z9+Y9+X9+AG9) -> 0 | AY9: =D9*(J9+K9+L9+AD9+AE9) -> 0 | AZ9: =D9*(J9+K9+L9) -> 0 | BA9: =D9*AC9 -> 0 | BB9: =D9*(AH9+AI9) -> 0 | BC9: =D9*(AH9+AI9) -> 0 | BD9: =D9*(AK9+W9) -> 0
AS10: =SUM(J10:AR10) -> 0 | AT10: =SUM(J10:O10) -> 0 | AU10: =SUM(P10:Z10) -> 0 | AV10: =SUM(AA10:AJ10) -> 0 | AX10: =D10*(P10+Q10+AL10+AE10+AA10+Z10+Y10+X10+AG10) -> 0 | AY10: =D10*(J10+K10+L10+AD10+AE10) -> 0 | AZ10: =D10*(J10+K10+L10) -> 0 | BA10: =D10*AC10 -> 0 | BB10: =D10*(AH10+AI10) -> 0 | BC10: =D10*(AH10+AI10) -> 0 | BD10: =D10*(AK10+W10) -> 0
AS11: =SUM(J11:AR11) -> 0 | AT11: =SUM(J11:O11) -> 0 | AU11: =SUM(P11:Z11) -> 0 | AV11: =SUM(AA11:AJ11) -> 0 | AX11: =D11*(P11+Q11+AL11+AE11+AA11+Z11+Y11+X11+AG11) -> 0 | AY11: =D11*(J11+K11+L11+AD11+AE11) -> 0 | AZ11: =D11*(J11+K11+L11) -> 0 | BA11: =D11*AC11 -> 0 | BB11: =D11*(AH11+AI11) -> 0 | BC11: =D11*(AH11+AI11) -> 0 | BD11: =D11*(AK11+W11) -> 0
AS12: =SUM(J12:AR12) -> 0 | AT12: =SUM(J12:O12) -> 0 | AU12: =SUM(P12:Z12) -> 0 | AV12: =SUM(AA12:AJ12) -> 0 | AX12: =D12*(P12+Q12+AL12+AE12+AA12+Z12+Y12+X12+AG12) -> 0 | AY12: =D12*(J12+K12+L12+AD12+AE12) -> 0 | AZ12: =D12*(J12+K12+L12) -> 0 | BA12: =D12*AC12 -> 0 | BB12: =D12*(AH12+AI12) -> 0 | BC12: =D12*(AH12+AI12) -> 0 | BD12: =D12*(AK12+W12) -> 0
AS13: =SUM(J13:AR13) -> 0 | AT13: =SUM(J13:O13) -> 0 | AU13: =SUM(P13:Z13) -> 0 | AV13: =SUM(AA13:AJ13) -> 0 | AX13: =D13*(P13+Q13+AL13+AE13+AA13+Z13+Y13+X13+AG13) -> 0 | AY13: =D13*(J13+K13+L13+AD13+AE13) -> 0 | AZ13: =D13*(J13+K13+L13) -> 0 | BA13: =D13*AC13 -> 0 | BB13: =D13*(AH13+AI13) -> 0 | BC13: =D13*(AH13+AI13) -> 0 | BD13: =D13*(AK13+W13) -> 0
AS14: =SUM(J14:AR14) -> 0 | AT14: =SUM(J14:O14) -> 0 | AU14: =SUM(P14:Z14) -> 0 | AV14: =SUM(AA14:AJ14) -> 0 | AX14: =D14*(P14+Q14+AL14+AE14+AA14+Z14+Y14+X14+AG14) -> 0 | AY14: =D14*(J14+K14+L14+AD14+AE14) -> 0 | AZ14: =D14*(J14+K14+L14) -> 0 | BA14: =D14*AC14 -> 0 | BB14: =D14*(AH14+AI14) -> 0 | BC14: =D14*(AH14+AI14) -> 0 | BD14: =D14*(AK14+W14) -> 0
AS15: =SUM(J15:AR15) -> 0 | AT15: =SUM(J15:O15) -> 0 | AU15: =SUM(P15:Z15) -> 0 | AV15: =SUM(AA15:AJ15) -> 0 | AX15: =D15*(P15+Q15+AL15+AE15+AA15+Z15+Y15+X15+AG15) -> 0 | AY15: =D15*(J15+K15+L15+AD15+AE15) -> 0 | AZ15: =D15*(J15+K15+L15) -> 0 | BA15: =D15*AC15 -> 0 | BB15: =D15*(AH15+AI15) -> 0 | BC15: =D15*(AH15+AI15) -> 0 | BD15: =D15*(AK15+W15) -> 0
AS16: =SUM(J16:AR16) -> 0 | AT16: =SUM(J16:O16) -> 0 | AU16: =SUM(P16:Z16) -> 0 | AV16: =SUM(AA16:AJ16) -> 0 | AX16: =D16*(P16+Q16+AL16+AE16+AA16+Z16+Y16+X16+AG16) -> 0 | AY16: =D16*(J16+K16+L16+AD16+AE16) -> 0 | AZ16: =D16*(J16+K16+L16) -> 0 | BA16: =D16*AC16 -> 0 | BB16: =D16*(AH16+AI16) -> 0 | BC16: =D16*(AH16+AI16) -> 0 | BD16: =D16*(AK16+W16) -> 0
AS17: =SUM(J17:AR17) -> 0 | AT17: =SUM(J17:O17) -> 0 | AU17: =SUM(P17:Z17) -> 0 | AV17: =SUM(AA17:AJ17) -> 0 | AX17: =D17*(P17+Q17+AL17+AE17+AA17+Z17+Y17+X17+AG17) -> 0 | AY17: =D17*(J17+K17+L17+AD17+AE17) -> 0 | AZ17: =D17*(J17+K17+L17) -> 0 | BA17: =D17*AC17 -> 0 | BB17: =D17*(AH17+AI17) -> 0 | BC17: =D17*(AH17+AI17) -> 0 | BD17: =D17*(AK17+W17) -> 0
... AS39: =SUM(J39:AR39) -> 0 | AT39: =SUM(J39:O39) -> 0 | AU39: =SUM(P39:Z39) -> 0 | AV39: =SUM(AA39:AJ39) -> 0 | AX39: =D39*(P39+Q39+AL39+AE39+AA39+Z39+Y39+X39+AG39) -> 0 | AY39: =D39*(J39+K39+L39+AD39+AE39) -> 0 | AZ39: =D39*(J39+K39+L39) -> 0 | BA39: =D39*AC39 -> 0 | BB39: =D39*(AH39+AI39) -> 0 | BC39: =D39*(AH39+AI39) -> 0 | BD39: =D39*(AK39+W39) -> 0
A40: 0 | AS40: =SUM(J40:AR40) -> 0 | AT40: =SUM(J40:O40) -> 0 | AU40: =SUM(P40:Z40) -> 0 | AV40: =SUM(AA40:AJ40) -> 0 | AX40: =D40*(P40+Q40+AL40+AE40+AA40+Z40+Y40+X40+AG40) -> 0 | AY40: =D40*(J40+K40+L40+AD40+AE40) -> 0 | AZ40: =D40*(J40+K40+L40) -> 0 | BA40: =D40*AC40 -> 0 | BB40: =D40*(AH40+AI40) -> 0 | BC40: =D40*(AH40+AI40) -> 0 | BD40: =D40*(AK40+W40) -> 0
A41: 103 | AS41: =SUM(J41:AR41) -> 0 | AT41: =SUM(J41:O41) -> 0 | AU41: =SUM(P41:Z41) -> 0 | AV41: =SUM(AA41:AJ41) -> 0 | AX41: =D41*(P41+Q41+AL41+AE41+AA41+Z41+Y41+X41) -> 0 | BA41: =D41*AC41 -> 0 | BD41: =D41*(AK41+W41) -> 0
A42: 104 | AS42: =SUM(J42:AR42) -> 0 | AT42: =SUM(J42:O42) -> 0 | AU42: =SUM(P42:Z42) -> 0 | AV42: =SUM(AA42:AJ42) -> 0 | AX42: =D42*(P42+Q42+AL42+AE42+AA42+Z42+Y42+X42) -> 0 | BA42: =D42*AC42 -> 0 | BD42: =D42*(AK42+W42) -> 0
A43: 105 | AS43: =SUM(J43:AR43) -> 0 | AT43: =SUM(J43:O43) -> 0 | AU43: =SUM(P43:Z43) -> 0 | AV43: =SUM(AA43:AJ43) -> 0 | AX43: =D43*(P43+Q43+AL43+AE43+AA43+Z43+Y43+X43) -> 0 | BA43: =D43*AC43 -> 0 | BD43: =D43*(AK43+W43) -> 0
A44: 106 | AS44: =SUM(J44:AR44) -> 0 | AT44: =SUM(J44:O44) -> 0 | AU44: =SUM(P44:Z44) -> 0 | AV44: =SUM(AA44:AJ44) -> 0 | AX44: =D44*(P44+Q44+AL44+AE44+AA44+Z44+Y44+X44) -> 0 | BA44: =D44*AC44 -> 0 | BD44: =D44*(AK44+W44) -> 0
A45: 107 | AS45: =SUM(J45:AR45) -> 0 | AT45: =SUM(J45:O45) -> 0 | AU45: =SUM(P45:Z45) -> 0 | AV45: =SUM(AA45:AJ45) -> 0 | AX45: =D45*(P45+Q45+AL45+AE45+AA45+Z45+Y45+X45) -> 0 | BA45: =D45*AC45 -> 0 | BD45: =D45*(AK45+W45) -> 0
A46: 108 | AS46: =SUM(J46:AR46) -> 0 | AT46: =SUM(J46:O46) -> 0 | AU46: =SUM(P46:Z46) -> 0 | AV46: =SUM(AA46:AJ46) -> 0 | AX46: =D46*(P46+Q46+AL46+AE46+AA46+Z46+Y46+X46) -> 0 | BA46: =D46*AC46 -> 0 | BD46: =D46*(AK46+W46) -> 0
A47: 109 | AS47: =SUM(J47:AR47) -> 0 | AT47: =SUM(J47:O47) -> 0 | AU47: =SUM(P47:Z47) -> 0 | AV47: =SUM(AA47:AJ47) -> 0 | AX47: =D47*(P47+Q47+AL47+AE47+AA47+Z47+Y47+X47) -> 0 | BA47: =D47*AC47 -> 0 | BD47: =D47*(AK47+W47) -> 0
A48: 110 | AS48: =SUM(J48:AR48) -> 0 | AT48: =SUM(J48:O48) -> 0 | AU48: =SUM(P48:Z48) -> 0 | AV48: =SUM(AA48:AJ48) -> 0 | AX48: =D48*(P48+Q48+AL48+AE48+AA48+Z48+Y48+X48) -> 0 | BA48: =D48*AC48 -> 0 | BD48: =D48*(AK48+W48) -> 0
A49: 111 | AS49: =SUM(J49:AR49) -> 0 | AT49: =SUM(J49:O49) -> 0 | AU49: =SUM(P49:Z49) -> 0 | AV49: =SUM(AA49:AJ49) -> 0 | AX49: =D49*(P49+Q49+AL49+AE49+AA49+Z49+Y49+X49) -> 0 | BA49: =D49*AC49 -> 0 | BD49: =D49*(AK49+W49) -> 0
A50: 112 | AS50: =SUM(J50:AR50) -> 0 | AT50: =SUM(J50:O50) -> 0 | AU50: =SUM(P50:Z50) -> 0 | AV50: =SUM(AA50:AJ50) -> 0 | AX50: =D50*(P50+Q50+AL50+AE50+AA50+Z50+Y50+X50) -> 0 | BA50: =D50*AC50 -> 0 | BD50: =D50*(AK50+W50) -> 0
A51: 113 | AS51: =SUM(J51:AR51) -> 0 | AT51: =SUM(J51:O51) -> 0 | AU51: =SUM(P51:Z51) -> 0 | AV51: =SUM(AA51:AJ51) -> 0 | AX51: =D51*(P51+Q51+AL51+AE51+AA51+Z51+Y51+X51) -> 0 | BA51: =D51*AC51 -> 0 | BD51: =D51*(AK51+W51) -> 0
A52: 114 | AS52: =SUM(J52:AR52) -> 0 | AT52: =SUM(J52:O52) -> 0 | AU52: =SUM(P52:Z52) -> 0 | AV52: =SUM(AA52:AJ52) -> 0 | AX52: =D52*(P52+Q52+AL52+AE52+AA52+Z52+Y52+X52) -> 0 | BA52: =D52*AC52 -> 0 | BD52: =D52*(AK52+W52) -> 0
... A938: 1000 | AS938: =SUM(J938:AR938) -> 0 | AT938: =SUM(J938:O938) -> 0 | AU938: =SUM(P938:Z938) -> 0 | AV938: =SUM(AA938:AJ938) -> 0 | AX938: =D938*(P938+Q938+AL938+AE938+AA938+Z938+Y938+X938) -> 0 | BA938: =D938*AC938 -> 0 | BD938: =D938*(AK938+W938) -> 0
AS939: =SUM(J939:AR939) -> 0 | AT939: =SUM(J939:O939) -> 0 | AU939: =SUM(P939:Z939) -> 0 | AV939: =SUM(AA939:AJ939) -> 0 | AX939: =D939*(P939+Q939+AL939+AE939+AA939+Z939+Y939+X939) -> 0 | BA939: =D939*AC939 -> 0 | BD939: =D939*(AK939+W939) -> 0
AS940: =SUM(J940:AR940) -> 0 | AT940: =SUM(J940:O940) -> 0 | AU940: =SUM(P940:Z940) -> 0 | AV940: =SUM(AA940:AJ940) -> 0 | AX940: =D940*(P940+Q940+AL940+AE940+AA940+Z940+Y940+X940) -> 0 | BA940: =D940*AC940 -> 0 | BD940: =D940*(AK940+W940) -> 0
AS941: =SUM(J941:AR941) -> 0 | AT941: =SUM(J941:O941) -> 0 | AU941: =SUM(P941:Z941) -> 0 | AV941: =SUM(AA941:AJ941) -> 0 | AX941: =D941*(P941+Q941+AL941+AE941+AA941+Z941+Y941+X941) -> 0 | BA941: =D941*AC941 -> 0 | BD941: =D941*(AK941+W941) -> 0
AS942: =SUM(J942:AR942) -> 0 | AT942: =SUM(J942:O942) -> 0 | AU942: =SUM(P942:Z942) -> 0 | AV942: =SUM(AA942:AJ942) -> 0 | AX942: =D942*(P942+Q942+AL942+AE942+AA942+Z942+Y942+X942) -> 0 | BA942: =D942*AC942 -> 0 | BD942: =D942*(AK942+W942) -> 0
AS943: =SUM(J943:AR943) -> 0 | AT943: =SUM(J943:O943) -> 0 | AU943: =SUM(P943:Z943) -> 0 | AV943: =SUM(AA943:AJ943) -> 0 | AX943: =D943*(P943+Q943+AL943+AE943+AA943+Z943+Y943+X943) -> 0 | BA943: =D943*AC943 -> 0 | BD943: =D943*(AK943+W943) -> 0
AS944: =SUM(J944:AR944) -> 0 | AT944: =SUM(J944:O944) -> 0 | AU944: =SUM(P944:Z944) -> 0 | AV944: =SUM(AA944:AJ944) -> 0 | AX944: =D944*(P944+Q944+AL944+AE944+AA944+Z944+Y944+X944) -> 0 | BA944: =D944*AC944 -> 0 | BD944: =D944*(AK944+W944) -> 0
AS945: =SUM(J945:AR945) -> 0 | AT945: =SUM(J945:O945) -> 0 | AU945: =SUM(P945:Z945) -> 0 | AV945: =SUM(AA945:AJ945) -> 0
B946: =SUBTOTAL(9,B4:B945) -> 0
...

Sheet TakeOff Intrusion
A1: No Local | B1: Nombres de Detail ou Points sur le plan | C1: Groupe de portes | D1: Distance (M) | E1: Descriptions au plan | F1: Local Panneau CP | L1: Détecteur de mouvement | M1: Contact magnétique | N1: Sirène | O1: Bouton d'urgence mural | P1: Clavier intrusion | Q1: Détecteur de mouvement type 1 | R1: Détecteur de mouvement type 2 | S1: Bouton d'urgence bureau | AS1: Nombre d'équipements | AU1: Câble 22/4 | AV1: Câble 18/2 | AW1: Câble résesau
J2: ANN | K2: BV | L2: DM | M2: CM | N2: SI | O2: BU | P2: CLI
J3: =J1024 -> 0 | K3: =K1024 -> 0 | L3: =L1024 -> 0 | M3: =M1024 -> 0 | N3: =N1024 -> 0 | O3: =O1024 -> 0 | P3: =P1024 -> 0 | Q3: =Q1024 -> 0 | ... AR3: =AR1024 -> 0
H4: 0
AS5: =SUM(J5:AR5) -> 0 | AU5: =D5*(K5+L5+M5+N5+O5+P5+Q5+R5+S5) -> 0 | AW5: =D5*J5 -> 0
AS6: =SUM(J6:AR6) -> 0 | AU6: =D6*(K6+L6+M6+N6+O6+P6+Q6+R6+S6) -> 0 | AW6: =D6*J6 -> 0
AS7: =SUM(J7:AR7) -> 0 | AU7: =D7*(K7+L7+M7+N7+O7+P7+Q7+R7+S7) -> 0 | AW7: =D7*J7 -> 0
AS8: =SUM(J8:AR8) -> 0 | AU8: =D8*(K8+L8+M8+N8+O8+P8+Q8+R8+S8) -> 0 | AW8: =D8*J8 -> 0
AS9: =SUM(J9:AR9) -> 0 | AU9: =D9*(K9+L9+M9+N9+O9+P9+Q9+R9+S9) -> 0 | AW9: =D9*J9 -> 0
AS10: =SUM(J10:AR10) -> 0 | AU10: =D10*(K10+L10+M10+N10+O10+P10+Q10+R10+S10) -> 0 | AW10: =D10*J10 -> 0
AS11: =SUM(J11:AR11) -> 0 | AU11: =D11*(K11+L11+M11+N11+O11+P11+Q11+R11+S11) -> 0 | AW11: =D11*J11 -> 0
AS12: =SUM(J12:AR12) -> 0 | AU12: =D12*(K12+L12+M12+N12+O12+P12+Q12+R12+S12) -> 0 | AW12: =D12*J12 -> 0
AS13: =SUM(J13:AR13) -> 0 | AU13: =D13*(K13+L13+M13+N13+O13+P13+Q13+R13+S13) -> 0 | AW13: =D13*J13 -> 0
AS14: =SUM(J14:AR14) -> 0 | AU14: =D14*(K14+L14+M14+N14+O14+P14+Q14+R14+S14) -> 0 | AW14: =D14*J14 -> 0
AS15: =SUM(J15:AR15) -> 0 | AU15: =D15*(K15+L15+M15+N15+O15+P15+Q15+R15+S15) -> 0 | AW15: =D15*J15 -> 0
AS16: =SUM(J16:AR16) -> 0 | AU16: =D16*(K16+L16+M16+N16+O16+P16+Q16+R16+S16) -> 0 | AW16: =D16*J16 -> 0
... AS33: =SUM(J33:AR33) -> 0 | AU33: =D33*(K33+L33+M33+N33+O33+P33+Q33+R33+S33) -> 0 | AW33: =D33*J33 -> 0
AS34: =SUM(J34:AR34) -> 0
AS35: =SUM(J35:AR35) -> 0
AS36: =SUM(J36:AR36) -> 0
AS37: =SUM(J37:AR37) -> 0
AS38: =SUM(J38:AR38) -> 0
AS39: =SUM(J39:AR39) -> 0
A40: 0 | AS40: =SUM(J40:AR40) -> 0
A41: 0 | AS41: =SUM(J41:AR41) -> 0
A42: 0 | AS42: =SUM(J42:AR42) -> 0
A43: 0 | AS43: =SUM(J43:AR43) -> 0
A44: 0 | AS44: =SUM(J44:AR44) -> 0
A45: 0 | AS45: =SUM(J45:AR45) -> 0
A46: 0 | AS46: =SUM(J46:AR46) -> 0
A47: 0 | AS47: =SUM(J47:AR47) -> 0
A48: 0 | AS48: =SUM(J48:AR48) -> 0
A49: 0 | AS49: =SUM(J49:AR49) -> 0
A50: 0 | AS50: =SUM(J50:AR50) -> 0
A51: 0 | AS51: =SUM(J51:AR51) -> 0
... A1015: 1000 | AS1015: =SUM(J1015:AR1015) -> 0
AS1016: =SUM(J1016:AR1016) -> 0
AS1017: =SUM(J1017:AR1017) -> 0
AS1018: =SUM(J1018:AR1018) -> 0
AS1019: =SUM(J1019:AR1019) -> 0
...
